2020-06-10 15:03:43,611 INFO: WebPipeliner startup [in /home/ubu/webpipeliner/app/__init__.py:25]
2020-06-10 15:03:51,737 ERROR: Exception on /favicon.ico [GET] [in /home/ubu/webpipeliner/.venv/lib/python3.6/site-packages/flask/app.py:1892]
Traceback (most recent call last):
  File "/home/ubu/webpipeliner/.venv/lib/python3.6/site-packages/flask/app.py", line 1950, in full_dispatch_request
    rv = self.dispatch_request()
  File "/home/ubu/webpipeliner/.venv/lib/python3.6/site-packages/flask/app.py", line 1926, in dispatch_request
    self.raise_routing_exception(req)
  File "/home/ubu/webpipeliner/.venv/lib/python3.6/site-packages/flask/app.py", line 1908, in raise_routing_exception
    raise request.routing_exception
  File "/home/ubu/webpipeliner/.venv/lib/python3.6/site-packages/flask/ctx.py", line 350, in match_request
    result = self.url_adapter.match(return_rule=True)
  File "/home/ubu/webpipeliner/.venv/lib/python3.6/site-packages/werkzeug/routing.py", line 1945, in match
    raise NotFound()
werkzeug.exceptions.NotFound: 404 Not Found: The requested URL was not found on the server. If you entered the URL manually please check your spelling and try again.

During handling of the above exception, another exception occurred:

Traceback (most recent call last):
  File "/home/ubu/webpipeliner/.venv/lib/python3.6/site-packages/flask/app.py", line 2447, in wsgi_app
    response = self.full_dispatch_request()
  File "/home/ubu/webpipeliner/.venv/lib/python3.6/site-packages/flask/app.py", line 1952, in full_dispatch_request
    rv = self.handle_user_exception(e)
  File "/home/ubu/webpipeliner/.venv/lib/python3.6/site-packages/flask/app.py", line 1816, in handle_user_exception
    return self.handle_http_exception(e)
  File "/home/ubu/webpipeliner/.venv/lib/python3.6/site-packages/flask/app.py", line 1744, in handle_http_exception
    return handler(e)
  File "/home/ubu/webpipeliner/app/errors.py", line 6, in not_found_error
    return render_template('404.html'), 404
  File "/home/ubu/webpipeliner/.venv/lib/python3.6/site-packages/flask/templating.py", line 140, in render_template
    ctx.app,
  File "/home/ubu/webpipeliner/.venv/lib/python3.6/site-packages/flask/templating.py", line 120, in _render
    rv = template.render(context)
  File "/home/ubu/webpipeliner/.venv/lib/python3.6/site-packages/jinja2/environment.py", line 1090, in render
    self.environment.handle_exception()
  File "/home/ubu/webpipeliner/.venv/lib/python3.6/site-packages/jinja2/environment.py", line 832, in handle_exception
    reraise(*rewrite_traceback_stack(source=source))
  File "/home/ubu/webpipeliner/.venv/lib/python3.6/site-packages/jinja2/_compat.py", line 28, in reraise
    raise value.with_traceback(tb)
  File "/home/ubu/webpipeliner/app/templates/404.html", line 1, in top-level template code
    {% extends "base.html" %}
  File "/home/ubu/webpipeliner/app/templates/base.html", line 1, in top-level template code
    {% extends 'bootstrap/base.html' %}
  File "/home/ubu/webpipeliner/.venv/lib/python3.6/site-packages/flask_bootstrap/templates/bootstrap/base.html", line 1, in top-level template code
    {% block doc -%}
  File "/home/ubu/webpipeliner/.venv/lib/python3.6/site-packages/flask_bootstrap/templates/bootstrap/base.html", line 4, in block "doc"
    {%- block html %}
  File "/home/ubu/webpipeliner/.venv/lib/python3.6/site-packages/flask_bootstrap/templates/bootstrap/base.html", line 20, in block "html"
    {% block body -%}
  File "/home/ubu/webpipeliner/.venv/lib/python3.6/site-packages/flask_bootstrap/templates/bootstrap/base.html", line 21, in block "body"
    {% block navbar %}
  File "/home/ubu/webpipeliner/app/templates/base.html", line 22, in block "navbar"
    {% if user.auth %}
  File "/home/ubu/webpipeliner/.venv/lib/python3.6/site-packages/jinja2/environment.py", line 471, in getattr
    return getattr(obj, attribute)
jinja2.exceptions.UndefinedError: 'user' is undefined
